<?xml version="1.0" encoding="utf-8"?>
<!-- This URDF was automatically created by SolidWorks to URDF Exporter! Originally created by Stephen Brawner (brawner@gmail.com) 
     Commit Version: 1.6.0-4-g7f85cfe  Build Version: 1.6.7995.38578
     For more information, please see http://wiki.ros.org/sw_urdf_exporter -->
<robot
  name="point_foot2">
  <link
    name="base_link">
    <inertial>
      <origin
        xyz="-0.000974322602317638 -2.60253375935215E-05 -0.141374199604637"
        rpy="0 0 0" />
      <mass
        value="2.9468763" />
      <inertia
        ixx="0.0296500"
        ixy="0.0000023"
        ixz="-0.0000368"
        iyy="0.0084810"
        iyz="-0.0000009"
        izz="0.0227884" />
    </inertial>
    <visual>
      <origin
        xyz="0 0 0"
        rpy="0 0 0" />
      <geometry>
        <mesh
          filename="package://point_foot2/meshes/base_link.STL" />
      </geometry>
      <material
        name="">
        <color
          rgba="1 1 1 1" />
      </material>
    </visual>
    <collision>
      <origin
        xyz="0 0 0"
        rpy="0 0 0" />
      <geometry>
        <mesh
          filename="package://point_foot2/meshes/base_link.STL" />
      </geometry>
    </collision>
  </link>
  <link
    name="left_hip_Link">
    <inertial>
      <origin
        xyz="-0.053218939743271 0.00117647536677846 -3.83049136038205E-05"
        rpy="0 0 0" />
      <mass
        value="1.1161220" />
      <inertia
        ixx="0.0009754"
        ixy="0.0000059"
        ixz="-0.0000006"
        iyy="0.0015883"
        iyz="-0.0000018"
        izz="0.0011149" />
    </inertial>
    <visual>
      <origin
        xyz="0 0 0"
        rpy="0 0 0" />
      <geometry>
        <mesh
          filename="package://point_foot2/meshes/left_hip_Link.STL" />
      </geometry>
      <material
        name="">
        <color
          rgba="1 1 1 1" />
      </material>
    </visual>
    <collision>
      <origin
        xyz="0 0 0"
        rpy="0 0 0" />
      <geometry>
        <mesh
          filename="package://point_foot2/meshes/left_hip_Link.STL" />
      </geometry>
    </collision>
  </link>
  <joint
    name="left_hip_joint"
    type="continuous">
    <origin
      xyz="-0.0301 0.08 -0.159"
      rpy="0 0 0" />
    <parent
      link="base_link" />
    <child
      link="left_hip_Link" />
    <axis
      xyz="1 0 0" />
  </joint>
  <link
    name="left_thigh_Link">
    <inertial>
      <origin
        xyz="-0.000925376041762085 0.0475153632426347 -0.0417189036582512"
        rpy="0 0 0" />
      <mass
        value="1.8233382" />
      <inertia
        ixx="0.0146510"
        ixy="0.0000105"
        ixz="0.0000250"
        iyy="0.0148132"
        iyz="0.0001761"
        izz="0.0016261" />
    </inertial>
    <visual>
      <origin
        xyz="0 0 0"
        rpy="0 0 0" />
      <geometry>
        <mesh
          filename="package://point_foot2/meshes/left_thigh_Link.STL" />
      </geometry>
      <material
        name="">
        <color
          rgba="0.752941176470588 0.752941176470588 0.752941176470588 1" />
      </material>
    </visual>
    <collision>
      <origin
        xyz="0 0 0"
        rpy="0 0 0" />
      <geometry>
        <mesh
          filename="package://point_foot2/meshes/left_thigh_Link.STL" />
      </geometry>
    </collision>
  </link>
  <joint
    name="left_thigh_joint"
    type="continuous">
    <origin
      xyz="-0.059 0.0306 0"
      rpy="0 0 0" />
    <parent
      link="left_hip_Link" />
    <child
      link="left_thigh_Link" />
    <axis
      xyz="0 1 0" />
  </joint>
  <link
    name="left_calf_Link">
    <inertial>
      <origin
        xyz="0.021886484628742 3.32396077727115E-05 -0.124091535731872"
        rpy="0 0 0" />
      <mass
        value="0.3721770" />
      <inertia
        ixx="0.0030581"
        ixy="0.0000059"
        ixz="0.0005067"
        iyy="0.0032814"
        iyz="-0.0000332"
        izz="0.0002720" />
    </inertial>
    <visual>
      <origin
        xyz="0 0 0"
        rpy="0 0 0" />
      <geometry>
        <mesh
          filename="package://point_foot2/meshes/left_calf_Link.STL" />
      </geometry>
      <material
        name="">
        <color
          rgba="1 1 1 1" />
      </material>
    </visual>
    <collision>
      <origin
        xyz="0 0 0"
        rpy="0 0 0" />
      <geometry>
        <mesh
          filename="package://point_foot2/meshes/left_calf_Link.STL" />
      </geometry>
    </collision>
  </link>
  <joint
    name="left_calf_joint"
    type="continuous">
    <origin
      xyz="0 0.0489 -0.2"
      rpy="0 0 0" />
    <parent
      link="left_thigh_Link" />
    <child
      link="left_calf_Link" />
    <axis
      xyz="0 1 0" />
  </joint>
  <link
    name="right_hip_Link">
    <inertial>
      <origin
        xyz="-0.0532189397432775 -0.00117647536677838 3.83049136032064E-05"
        rpy="0 0 0" />
      <mass
        value="1.1161220" />
      <inertia
        ixx="0.0009754"
        ixy="-0.0000059"
        ixz="0.0000006"
        iyy="0.0015883"
        iyz="-0.0000018"
        izz="0.0011149" />
    </inertial>
    <visual>
      <origin
        xyz="0 0 0"
        rpy="0 0 0" />
      <geometry>
        <mesh
          filename="package://point_foot2/meshes/right_hip_Link.STL" />
      </geometry>
      <material
        name="">
        <color
          rgba="1 1 1 1" />
      </material>
    </visual>
    <collision>
      <origin
        xyz="0 0 0"
        rpy="0 0 0" />
      <geometry>
        <mesh
          filename="package://point_foot2/meshes/right_hip_Link.STL" />
      </geometry>
    </collision>
  </link>
  <joint
    name="right_hip_joint"
    type="continuous">
    <origin
      xyz="-0.0301 -0.08 -0.159"
      rpy="0 0 0" />
    <parent
      link="base_link" />
    <child
      link="right_hip_Link" />
    <axis
      xyz="1 0 0" />
  </joint>
  <link
    name="right_thigh_Link">
    <inertial>
      <origin
        xyz="-0.000326512135141829 -0.0475223934194865 -0.042222531585022"
        rpy="0 0 0" />
      <mass
        value="1.8233382" />
      <inertia
        ixx="0.0146510"
        ixy="-0.0000381"
        ixz="-0.0000263"
        iyy="0.0148142"
        iyz="-0.0001761"
        izz="0.0016271" />
    </inertial>
    <visual>
      <origin
        xyz="0 0 0"
        rpy="0 0 0" />
      <geometry>
        <mesh
          filename="package://point_foot2/meshes/right_thigh_Link.STL" />
      </geometry>
      <material
        name="">
        <color
          rgba="0.752941176470588 0.752941176470588 0.752941176470588 1" />
      </material>
    </visual>
    <collision>
      <origin
        xyz="0 0 0"
        rpy="0 0 0" />
      <geometry>
        <mesh
          filename="package://point_foot2/meshes/right_thigh_Link.STL" />
      </geometry>
    </collision>
  </link>
  <joint
    name="right_thigh_joint"
    type="continuous">
    <origin
      xyz="-0.059 -0.0306 0"
      rpy="0 0 0" />
    <parent
      link="right_hip_Link" />
    <child
      link="right_thigh_Link" />
    <axis
      xyz="0 1 0" />
  </joint>
  <link
    name="right_calf_Link">
    <inertial>
      <origin
        xyz="0.0218752367358313 -3.3239607772656E-05 -0.12409351903896"
        rpy="0 0 0" />
      <mass
        value="0.3721770" />
      <inertia
        ixx="0.0030579"
        ixy="-0.0000059"
        ixz="0.0005072"
        iyy="0.0032814"
        iyz="0.0000332"
        izz="0.0002722" />
    </inertial>
    <visual>
      <origin
        xyz="0 0 0"
        rpy="0 0 0" />
      <geometry>
        <mesh
          filename="package://point_foot2/meshes/right_calf_Link.STL" />
      </geometry>
      <material
        name="">
        <color
          rgba="1 1 1 1" />
      </material>
    </visual>
    <collision>
      <origin
        xyz="0 0 0"
        rpy="0 0 0" />
      <geometry>
        <mesh
          filename="package://point_foot2/meshes/right_calf_Link.STL" />
      </geometry>
    </collision>
  </link>
  <joint
    name="right_calf_joint"
    type="continuous">
    <origin
      xyz="0 -0.0489 -0.2"
      rpy="0 0 0" />
    <parent
      link="right_thigh_Link" />
    <child
      link="right_calf_Link" />
    <axis
      xyz="0 1 0" />
  </joint>
</robot>